/bin/sh: sox: command not found
SoX could not be found!

    If you do not have SoX, proceed here:
     - - - http://sox.sourceforge.net/ - - -

    If you do (or think that you should) have SoX, double-check your
    path variables.
    
False
Using device: cpu
New model initialized.
Training for epoch 0
Traceback (most recent call last):
  File "main.py", line 9, in <module>
    t.train()
  File "/home/xuranzeng/thesis_git/code/trainer/trainer.py", line 88, in train
    loss, cls_loss, mmd_loss = self.model(batch_s, batch_b, "train")
  File "/home/xuranzeng/.conda/envs/xuran/lib/python3.8/site-packages/torch/nn/modules/module.py", line 1051, in _call_impl
    return forward_call(*input, **kwargs)
  File "/home/xuranzeng/thesis_git/code/model/fnn.py", line 48, in forward
    cls_loss = self.cls_loss_fn(logits_s, batch_s["label"])
  File "/home/xuranzeng/thesis_git/code/loss/loss.py", line 10, in __call__
    return self.loss_fn(
  File "/home/xuranzeng/.conda/envs/xuran/lib/python3.8/site-packages/torch/nn/modules/module.py", line 1051, in _call_impl
    return forward_call(*input, **kwargs)
  File "/home/xuranzeng/.conda/envs/xuran/lib/python3.8/site-packages/torch/nn/modules/loss.py", line 1120, in forward
    return F.cross_entropy(input, target, weight=self.weight,
  File "/home/xuranzeng/.conda/envs/xuran/lib/python3.8/site-packages/torch/nn/functional.py", line 2824, in cross_entropy
    return torch._C._nn.cross_entropy_loss(input, target, weight, _Reduction.get_enum(reduction), ignore_index)
IndexError: Target 7 is out of bounds.
